Traceback (most recent call last):
  File "/Users/ethanvo/builds/pyscf/projected-cvs/pyscf/pyscf/lib/misc.py", line 54, in load_library
    return numpy.ctypeslib.load_library(libname, _loaderpath)
           ^^^^^^^^^^^^^^^^^^^^^^^^^^^^^^^^^^^^^^^^^^^^^^^^^^
  File "/Users/ethanvo/builds/spack/develop/spack/var/spack/environments/global/.spack-env/view/lib/python3.11/site-packages/numpy/ctypeslib.py", line 156, in load_library
    return ctypes.cdll[libpath]
           ~~~~~~~~~~~^^^^^^^^^
  File "/Users/ethanvo/builds/spack/develop/spack/opt/spack/darwin-sequoia-m1/apple-clang-16.0.0/python-3.11.9-bwx7jxwzkif7fqxwsowc4eclxyjnjtpw/lib/python3.11/ctypes/__init__.py", line 451, in __getitem__
    return getattr(self, name)
           ^^^^^^^^^^^^^^^^^^^
  File "/Users/ethanvo/builds/spack/develop/spack/opt/spack/darwin-sequoia-m1/apple-clang-16.0.0/python-3.11.9-bwx7jxwzkif7fqxwsowc4eclxyjnjtpw/lib/python3.11/ctypes/__init__.py", line 446, in __getattr__
    dll = self._dlltype(name)
          ^^^^^^^^^^^^^^^^^^^
  File "/Users/ethanvo/builds/spack/develop/spack/opt/spack/darwin-sequoia-m1/apple-clang-16.0.0/python-3.11.9-bwx7jxwzkif7fqxwsowc4eclxyjnjtpw/lib/python3.11/ctypes/__init__.py", line 376, in __init__
    self._handle = _dlopen(self._name, mode)
                   ^^^^^^^^^^^^^^^^^^^^^^^^^
OSError: dlopen(/Users/ethanvo/builds/pyscf/projected-cvs/pyscf/pyscf/lib/libcgto.dylib, 0x0006): Library not loaded: /opt/homebrew/opt/gcc/lib/gcc/current/libquadmath.0.dylib
  Referenced from: <12A1C82B-DB28-3325-B9D3-CCDBC0132CE2> /Users/ethanvo/builds/pyscf/projected-cvs/pyscf/pyscf/lib/deps/lib/libcint.5.1.0.dylib
  Reason: tried: '/opt/homebrew/opt/gcc/lib/gcc/current/libquadmath.0.dylib' (no such file), '/System/Volumes/Preboot/Cryptexes/OS/opt/homebrew/opt/gcc/lib/gcc/current/libquadmath.0.dylib' (no such file), '/opt/homebrew/opt/gcc/lib/gcc/current/libquadmath.0.dylib' (no such file), '/usr/local/lib/libquadmath.0.dylib' (no such file), '/usr/lib/libquadmath.0.dylib' (no such file, not in dyld cache)

During handling of the above exception, another exception occurred:

Traceback (most recent call last):
  File "/Users/ethanvo/projects/li_ec_clusters/HY_cluster/reaction/carving.py", line 4, in <module>
    from pyscf.lib import logger
  File "/Users/ethanvo/builds/pyscf/projected-cvs/pyscf/pyscf/__init__.py", line 114, in <module>
    from pyscf import gto
  File "/Users/ethanvo/builds/pyscf/projected-cvs/pyscf/pyscf/gto/__init__.py", line 19, in <module>
    from pyscf.gto import mole
  File "/Users/ethanvo/builds/pyscf/projected-cvs/pyscf/pyscf/gto/mole.py", line 46, in <module>
    from pyscf.gto import moleintor
  File "/Users/ethanvo/builds/pyscf/projected-cvs/pyscf/pyscf/gto/moleintor.py", line 29, in <module>
    libcgto = lib.load_library('libcgto')
              ^^^^^^^^^^^^^^^^^^^^^^^^^^^
  File "/Users/ethanvo/builds/pyscf/projected-cvs/pyscf/pyscf/lib/misc.py", line 62, in load_library
    return numpy.ctypeslib.load_library(libname, libpath)
           ^^^^^^^^^^^^^^^^^^^^^^^^^^^^^^^^^^^^^^^^^^^^^^
  File "/Users/ethanvo/builds/spack/develop/spack/var/spack/environments/global/.spack-env/view/lib/python3.11/site-packages/numpy/ctypeslib.py", line 156, in load_library
    return ctypes.cdll[libpath]
           ~~~~~~~~~~~^^^^^^^^^
  File "/Users/ethanvo/builds/spack/develop/spack/opt/spack/darwin-sequoia-m1/apple-clang-16.0.0/python-3.11.9-bwx7jxwzkif7fqxwsowc4eclxyjnjtpw/lib/python3.11/ctypes/__init__.py", line 451, in __getitem__
    return getattr(self, name)
           ^^^^^^^^^^^^^^^^^^^
  File "/Users/ethanvo/builds/spack/develop/spack/opt/spack/darwin-sequoia-m1/apple-clang-16.0.0/python-3.11.9-bwx7jxwzkif7fqxwsowc4eclxyjnjtpw/lib/python3.11/ctypes/__init__.py", line 446, in __getattr__
    dll = self._dlltype(name)
          ^^^^^^^^^^^^^^^^^^^
  File "/Users/ethanvo/builds/spack/develop/spack/opt/spack/darwin-sequoia-m1/apple-clang-16.0.0/python-3.11.9-bwx7jxwzkif7fqxwsowc4eclxyjnjtpw/lib/python3.11/ctypes/__init__.py", line 376, in __init__
    self._handle = _dlopen(self._name, mode)
                   ^^^^^^^^^^^^^^^^^^^^^^^^^
OSError: dlopen(/Users/ethanvo/builds/pyscf/projected-cvs/pyscf/pyscf/lib/libcgto.dylib, 0x0006): Library not loaded: /opt/homebrew/opt/gcc/lib/gcc/current/libquadmath.0.dylib
  Referenced from: <12A1C82B-DB28-3325-B9D3-CCDBC0132CE2> /Users/ethanvo/builds/pyscf/projected-cvs/pyscf/pyscf/lib/deps/lib/libcint.5.1.0.dylib
  Reason: tried: '/opt/homebrew/opt/gcc/lib/gcc/current/libquadmath.0.dylib' (no such file), '/System/Volumes/Preboot/Cryptexes/OS/opt/homebrew/opt/gcc/lib/gcc/current/libquadmath.0.dylib' (no such file), '/opt/homebrew/opt/gcc/lib/gcc/current/libquadmath.0.dylib' (no such file), '/usr/local/lib/libquadmath.0.dylib' (no such file), '/usr/lib/libquadmath.0.dylib' (no such file, not in dyld cache)
